2024-08-05 12:43:20,754 get 'MONGO_CON_STR' cast2024-08-05 12:43:59,453 
def accumulate(self, *args, **kwargs):
    return 1

2024-08-05 12:43:59,456 
def bookreader_api_call_task(path):
    return 1

2024-08-05 12:43:59,456 
def chunks(task, it, n):
    return 1

2024-08-05 12:43:59,457 
def unlock_chord(self, group_id, callback, interval=0, max_retries=1, result=2, Result=3, GroupResult=4, result_from_tuple=5, **kwargs):
    return 1

2024-08-05 12:43:59,457 
def group(self, tasks, result, group_id, partial_args, add_to_parent=0):
    return 1

2024-08-05 12:43:59,457 
def xmap(task, it):
    return 1

2024-08-05 12:43:59,458 
def backend_cleanup():
    return 1

2024-08-05 12:43:59,458 
def chain(*args, **kwargs):
    return 1

2024-08-05 12:43:59,458 
def scheduled_delete_pdf_img():
    return 1

2024-08-05 12:43:59,458 
def xstarmap(task, it):
    return 1

2024-08-05 12:43:59,458 
def scheduled_create_update_image():
    return 1

2024-08-05 12:43:59,458 
def chord(self, header, body, partial_args=0, interval=1, countdown=2, max_retries=3, eager=4, **kwargs):
    return 1

2024-08-05 12:43:59,478 Start from server, version: 0.9, properties: {'capabilities': {'publisher_confirms': True, 'exchange_exchange_bindings': True, 'basic.nack': True, 'consumer_cancel_notify': True, 'connection.blocked': True, 'consumer_priorities': True, 'authentication_failure_close': True, 'per_consumer_qos': True, 'direct_reply_to': True}, 'cluster_name': 'rabbit@rabbit1', 'copyright': 'Copyright (c) 2007-2024 Broadcom Inc and/or its subsidiaries', 'information': 'Licensed under the MPL 2.0. Website: https://rabbitmq.com', 'platform': 'Erlang/OTP 26.2.5.2', 'product': 'RabbitMQ', 'version': '3.13.6'}, mechanisms: [b'PLAIN', b'AMQPLAIN'], locales: ['en_US']
2024-08-05 12:43:59,479 using channel_id: 1
2024-08-05 12:43:59,480 Channel open
2024-08-05 12:43:59,512 Internal Server Error: /api/bookreader/bskn2/ktp2019-bskn2.pdf
Traceback (most recent call last):
  File "/usr/local/lib/python3.10/site-packages/django/core/handlers/exception.py", line 55, in inner
    response = get_response(request)
  File "/usr/local/lib/python3.10/site-packages/django/core/handlers/base.py", line 197, in _get_response
    response = wrapped_callback(request, *callback_args, **callback_kwargs)
  File "/usr/local/lib/python3.10/site-packages/django/views/decorators/csrf.py", line 54, in wrapped_view
    return view_func(*args, **kwargs)
  File "/usr/local/lib/python3.10/site-packages/django/views/generic/base.py", line 103, in view
    return self.dispatch(request, *args, **kwargs)
  File "/usr/local/lib/python3.10/site-packages/rest_framework/views.py", line 509, in dispatch
    response = self.handle_exception(exc)
  File "/usr/local/lib/python3.10/site-packages/rest_framework/views.py", line 469, in handle_exception
    self.raise_uncaught_exception(exc)
  File "/usr/local/lib/python3.10/site-packages/rest_framework/views.py", line 480, in raise_uncaught_exception
    raise exc
  File "/usr/local/lib/python3.10/site-packages/rest_framework/views.py", line 506, in dispatch
    response = handler(request, *args, **kwargs)
  File "/code/./api/views.py", line 141, in get
    result = get_img_info(entity=entity,pdf_name=pdf_name)
  File "/code/./api/services.py", line 138, in get_img_info
    thumbnail = DOMAIN_NAME + "/download/" + attachment['thumbnail'].strip("/archive/")
KeyError: 'thumbnail'
2024-08-05 12:43:59,535 Internal Server Error: /api/bookreader/bskn2/ktp2019-bskn2.pdf
Traceback (most recent call last):
  File "/usr/local/lib/python3.10/site-packages/django/core/handlers/exception.py", line 55, in inner
    response = get_response(request)
  File "/usr/local/lib/python3.10/site-packages/django/core/handlers/base.py", line 197, in _get_response
    response = wrapped_callback(request, *callback_args, **callback_kwargs)
  File "/usr/local/lib/python3.10/site-packages/django/views/decorators/csrf.py", line 54, in wrapped_view
    return view_func(*args, **kwargs)
  File "/usr/local/lib/python3.10/site-packages/django/views/generic/base.py", line 103, in view
    return self.dispatch(request, *args, **kwargs)
  File "/usr/local/lib/python3.10/site-packages/rest_framework/views.py", line 509, in dispatch
    response = self.handle_exception(exc)
  File "/usr/local/lib/python3.10/site-packages/rest_framework/views.py", line 469, in handle_exception
    self.raise_uncaught_exception(exc)
  File "/usr/local/lib/python3.10/site-packages/rest_framework/views.py", line 480, in raise_uncaught_exception
    raise exc
  File "/usr/local/lib/python3.10/site-packages/rest_framework/views.py", line 506, in dispatch
    response = handler(request, *args, **kwargs)
  File "/code/./api/views.py", line 141, in get
    result = get_img_info(entity=entity,pdf_name=pdf_name)
  File "/code/./api/services.py", line 138, in get_img_info
    thumbnail = DOMAIN_NAME + "/download/" + attachment['thumbnail'].strip("/archive/")
KeyError: 'thumbnail'
2024-08-05 12:43:59,564 Internal Server Error: /api/bookreader/bskn2/ktp2019-bskn2.pdf
Traceback (most recent call last):
  File "/usr/local/lib/python3.10/site-packages/django/core/handlers/exception.py", line 55, in inner
    response = get_response(request)
  File "/usr/local/lib/python3.10/site-packages/django/core/handlers/base.py", line 197, in _get_response
    response = wrapped_callback(request, *callback_args, **callback_kwargs)
  File "/usr/local/lib/python3.10/site-packages/django/views/decorators/csrf.py", line 54, in wrapped_view
    return view_func(*args, **kwargs)
  File "/usr/local/lib/python3.10/site-packages/django/views/generic/base.py", line 103, in view
    return self.dispatch(request, *args, **kwargs)
  File "/usr/local/lib/python3.10/site-packages/rest_framework/views.py", line 509, in dispatch
    response = self.handle_exception(exc)
  File "/usr/local/lib/python3.10/site-packages/rest_framework/views.py", line 469, in handle_exception
    self.raise_uncaught_exception(exc)
  File "/usr/local/lib/python3.10/site-packages/rest_framework/views.py", line 480, in raise_uncaught_exception
    raise exc
  File "/usr/local/lib/python3.10/site-packages/rest_framework/views.py", line 506, in dispatch
    response = handler(request, *args, **kwargs)
  File "/code/./api/views.py", line 141, in get
    result = get_img_info(entity=entity,pdf_name=pdf_name)
  File "/code/./api/services.py", line 138, in get_img_info
    thumbnail = DOMAIN_NAME + "/download/" + attachment['thumbnail'].strip("/archive/")
KeyError: 'thumbnail'
2024-08-05 12:43:59,588 Internal Server Error: /api/bookreader/bskn2/ktp2019-bskn2.pdf
Traceback (most recent call last):
  File "/usr/local/lib/python3.10/site-packages/django/core/handlers/exception.py", line 55, in inner
    response = get_response(request)
  File "/usr/local/lib/python3.10/site-packages/django/core/handlers/base.py", line 197, in _get_response
    response = wrapped_callback(request, *callback_args, **callback_kwargs)
  File "/usr/local/lib/python3.10/site-packages/django/views/decorators/csrf.py", line 54, in wrapped_view
    return view_func(*args, **kwargs)
  File "/usr/local/lib/python3.10/site-packages/django/views/generic/base.py", line 103, in view
    return self.dispatch(request, *args, **kwargs)
  File "/usr/local/lib/python3.10/site-packages/rest_framework/views.py", line 509, in dispatch
    response = self.handle_exception(exc)
  File "/usr/local/lib/python3.10/site-packages/rest_framework/views.py", line 469, in handle_exception
    self.raise_uncaught_exception(exc)
  File "/usr/local/lib/python3.10/site-packages/rest_framework/views.py", line 480, in raise_uncaught_exception
    raise exc
  File "/usr/local/lib/python3.10/site-packages/rest_framework/views.py", line 506, in dispatch
    response = handler(request, *args, **kwargs)
  File "/code/./api/views.py", line 141, in get
    result = get_img_info(entity=entity,pdf_name=pdf_name)
  File "/code/./api/services.py", line 138, in get_img_info
    thumbnail = DOMAIN_NAME + "/download/" + attachment['thumbnail'].strip("/archive/")
KeyError: 'thumbnail'
2024-08-05 12:44:02,590 Internal Server Error: /api/bookreader/bskn2/ktp2019-bskn2.pdf
Traceback (most recent call last):
  File "/usr/local/lib/python3.10/site-packages/django/core/handlers/exception.py", line 55, in inner
    response = get_response(request)
  File "/usr/local/lib/python3.10/site-packages/django/core/handlers/base.py", line 197, in _get_response
    response = wrapped_callback(request, *callback_args, **callback_kwargs)
  File "/usr/local/lib/python3.10/site-packages/django/views/decorators/csrf.py", line 54, in wrapped_view
    return view_func(*args, **kwargs)
  File "/usr/local/lib/python3.10/site-packages/django/views/generic/base.py", line 103, in view
    return self.dispatch(request, *args, **kwargs)
  File "/usr/local/lib/python3.10/site-packages/rest_framework/views.py", line 509, in dispatch
    response = self.handle_exception(exc)
  File "/usr/local/lib/python3.10/site-packages/rest_framework/views.py", line 469, in handle_exception
    self.raise_uncaught_exception(exc)
  File "/usr/local/lib/python3.10/site-packages/rest_framework/views.py", line 480, in raise_uncaught_exception
    raise exc
  File "/usr/local/lib/python3.10/site-packages/rest_framework/views.py", line 506, in dispatch
    response = handler(request, *args, **kwargs)
  File "/code/./api/views.py", line 141, in get
    result = get_img_info(entity=entity,pdf_name=pdf_name)
  File "/code/./api/services.py", line 138, in get_img_info
    thumbnail = DOMAIN_NAME + "/download/" + attachment['thumbnail'].strip("/archive/")
KeyError: 'thumbnail'
